<?xml version="1.0" encoding="utf-8"?>

<robot name="smartsix">

    <link name="base_link">
        <!--<inertial></inertial>-->

        <visual>
            <origin xyz="0 0 0" rpy="0 0 0"/>
            <geometry>
                <mesh filename="package://comau_description/meshes/visual/base_link.dae"/>
            </geometry>
            <material name=""/>
        </visual>

        <collision>
            <origin xyz="0 0 0" rpy="0 0 0"/>
            <geometry>
                <mesh filename="package://comau_description/meshes/collision/base_link.stl"/>
            </geometry>
        </collision>
    </link>

    <link name="link1">
        <visual>
            <origin xyz="0 0 0" rpy="0 0 0"/>
            <geometry>
                <mesh filename="package://comau_description/meshes/visual/link1.dae"/>
            </geometry>
            <material name=""/>
        </visual>

        <collision>
            <origin xyz="0 0 0" rpy="0 0 0"/>
            <geometry>
                <mesh filename="package://comau_description/meshes/collision/link1.stl"/>
            </geometry>
        </collision>
    </link>

    <link name="link2">
        <visual>
            <origin xyz="0 0 0" rpy="0 0 0"/>
            <geometry>
                <mesh filename="package://comau_description/meshes/visual/link2.dae"/>
            </geometry>
            <material name=""/>
        </visual>

        <collision>
            <origin xyz="0 0 0" rpy="0 0 0"/>
            <geometry>
                <mesh filename="package://comau_description/meshes/collision/link2.stl"/>
            </geometry>
        </collision>
    </link>

    <link name= "link3">
        <visual>
            <origin xyz="0 0 0" rpy ="0 0 0"/>
            <geometry>
                    <mesh filename="package://comau_description/meshes/visual/link3.dae"/>
            </geometry>
        </visual>
        <collision>
            <origin xyz="0 0 0" rpy="0 0 0"/>
            <geometry>
                <mesh filename="package://comau_description/meshes/collision/link3.stl"/>
            </geometry>
        </collision>
    </link>

    <!--<link name="link3">
    
    </link>

    <link name="link4">
    
    </link>

    <link name="link5">
    
    </link>

    <link name="link6">
    
    </link>

    <link name="flange">
    
    </link>-->

    <joint name="joint1" type="revolute">
        <parent link="base_link"/>
        <child link="link1"/>
        <origin xyz="0 0 0" rpy="0 0 0"/>
        <axis xyz="0 0 1"/>
        <limit lower="-2.967" upper="2.967" effort="12" velocity="2.443"/>
    </joint>

    <joint name="joint2" type="revolute">
        <parent link="link1"/>
        <child link="link2"/>
        <origin xyz="0.15 0 0.45" rpy="-1.5708 0 0"/>
        <axis xyz="0 0 1"/>
        <limit lower="-1.4835" upper="2.7052" effort="12" velocity="2.792"/>
    </joint>

    <joint name="joint3" type="revolute">
        <origin xyz="0 -0.59 0" rpy= "0 0 -1.5708"></origin>
        <parent link="link2"/>
        <child link="link3"/>
        <axis xyz="0 0.0 1"/>
        <limit lower="-1.5707" upper="1.3962" effort="12" velocity="2.967"/>
        
    </joint>

    <!-- <joint name="joint4" type="revolute">

    </joint>

    <joint name="joint5" type="revolute">

    </joint>

    <joint name="joint6" type="revolute">

    </joint> -->
    
</robot>