<?xml version="1.0"?>
<robot name="fanuc">
    <link name="base_link">
        <visual>
            <geometry>
                <mesh filename="package://fanuc_description/meshes/visual/link_0.dae" />
            </geometry>
        </visual>
        <collision>
            <geometry>
                <mesh filename="package://fanuc_description/meshes/collision/link_0.stl" />
            </geometry>
        </collision>
    </link>
    <link name="link1">
        <visual>
            <geometry>
                <mesh filename="package://fanuc_description/meshes/visual/link_1.dae" />
            </geometry>
        </visual>
        <collision>
            <geometry>
                <mesh filename="package://fanuc_description/meshes/collision/link_1.stl" />
            </geometry>
        </collision>
    </link>

    <link name="link2">
        <visual>
            <origin xyz="-0.15 -0.525 0" rpy="-1.57 0 0" />
            <geometry>
                <mesh filename="package://fanuc_description/meshes/visual/link_2.dae" />
            </geometry>
        </visual>
        <collision>
            <origin xyz="-0.15 -0.525 0" rpy="-1.57 0 0" />
            <geometry>
                <mesh filename="package://fanuc_description/meshes/collision/link_2.stl" />
            </geometry>
        </collision>
    </link>

    <link name="link3">
        <visual>
            <origin xyz="-1.3 0.15 0" rpy="1.57 3.14 1.57"/>
            <geometry>
                <mesh filename="package://fanuc_description/meshes/visual/link_3.dae" />
            </geometry>
        </visual> 
        <collision>
            <origin xyz="-1.3 0.15 0" rpy="1.57 3.14 1.57"/>
            <geometry>
                <mesh filename="package://fanuc_description/meshes/collision/link_3.stl" />
            </geometry>
        </collision>
    </link>

    <link name="link4">
        <visual>
            <origin xyz="1.475 0 -0.3" rpy="0 -1.5708 0"/>
            <geometry>
                <mesh filename="package://fanuc_description/meshes/visual/link_4.dae" />
            </geometry>
        </visual> 
        <collision>
            <origin xyz="1.475 0 -0.3" rpy="0 -1.5708 0"/>
            <geometry>
                <mesh filename="package://fanuc_description/meshes/collision/link_4.stl" />
            </geometry>
        </collision>
    </link>

    <link name="link5">
        <visual>
            <origin xyz="-1.45 -1.166 0" rpy="1.5708 0 1.5708"/>
            <geometry>
                <mesh filename="package://fanuc_description/meshes/visual/link_5.dae" />
            </geometry>
        </visual> 
        <collision>
            <origin xyz="-1.45 -1.166 0" rpy="1.5708 0 1.5708"/>
            <geometry>
                <mesh filename="package://fanuc_description/meshes/collision/link_5.stl" />
            </geometry>
        </collision>
    </link>

    <link name="link6">
        <visual>
            <origin xyz="0.01 0 -0.05" rpy="0 0 0"/>
            <geometry>
                <mesh filename="package://fanuc_description/meshes/visual/link_6.dae" />
            </geometry>
        </visual> 
        <collision>
            <origin xyz="0 0 0" rpy="0 0 0"/>
            <geometry>
                <mesh filename="package://fanuc_description/meshes/collision/link_6.stl" />
            </geometry>
        </collision>
    </link>
    <link name="link7"></link>
    <!--    
    <link name="link5">
        
    </link>
    <link name="link6">
        
    </link>
    <link name="flange">
        
    </link>  -->

    <joint name="joint1" type="revolute">
        <parent link="base_link" />
        <child link="link1" />
        <origin xyz="0 0 0" rpy="0 0 0" />
        <axis xyz="0 0 1" />
        <limit lower="-2.967" upper="2.967" effort="12" velocity="2.433" />
    </joint>

    <joint name="joint_2" type="revolute">
        <parent link="link1" />
        <child link="link2" />
        <origin xyz="0.15 0.0 0.525" rpy="+1.57 0 0" />
        <axis xyz="0 0 1" />
        <limit lower="-2.967" upper="2.967" effort="12" velocity="2.433" />
    </joint>

    <joint name="joint_3" type="revolute">
        <parent link="link2" />
        <child link="link3" />
        <origin xyz="0 0.79 0" rpy="0 0 1.57" />
        <axis xyz="0 0 1" />
        <limit lower="-2.967" upper="2.967" effort="12" velocity="2.433" />
    </joint>

    <joint name="joint_4" type="revolute">
        <parent link="link3" />
        <child link="link4" />
        <origin xyz="0.15 -0.15 0" rpy="1.57 0 0 " />
        <axis xyz="0 0 1" />
        <limit lower="-2.967" upper="2.967" effort="12" velocity="2.433" />
    </joint>

    <joint name="joint_5" type="revolute">
        <parent link="link4" />
        <child link="link5" />
        <origin xyz="0 0 0.86" rpy="+1.57 0 -3.14" />
        <axis xyz="0 0 1" />
        <limit lower="-2.967" upper="2.967" effort="12" velocity="2.433" />
    </joint>

    <joint name="joint_6" type="revolute">
        <parent link="link5" />
        <child link="link6" />
        <origin xyz="0 0 0" rpy="-1.57 0 0" />
        <axis xyz="0 0 1" />
        <limit lower="-2.967" upper="2.967" effort="12" velocity="2.433" />
    </joint>

    <joint name="flange" type="fixed">
        <parent link="link6" />
        <child link="link7" />
        <origin xyz="0 0 0.1" rpy="0 0 0" />
        <axis xyz="0 0 1" />
        <limit lower="-2.967" upper="2.967" effort="12" velocity="2.433" />
    </joint>


    <!-- <joint name="joint_4" type="revolute">
        <parent link="link3"/>
        <child link="link4"/>
        <origin xyz="0 0 0" rpy="0 0 0" />
        <axis xyz="0 0 1"/>
        <limit lower="-2.967" upper="2.967" effort="12" velocity="2.433"/>
    </joint> -->


    <!-- <joint name="joint2" type="revolute">
        
    </joint>
    
    <joint name="joint3" type="revolute">
        
    </joint>

    <joint name="joint3" type="revolute">
        
    </joint>

    <joint name="joint4" type="revolute">
        
    </joint>

    <joint name="joint5" type="revolute">
        
    </joint>
    
    <joint name="joint6" type="revolute">
        
    </joint>

    <joint name="flange" type="revolute">
        
    </joint> -->
</robot>